Workbook

Sheet Summary
A1: MASTER INVENTORY SUMMARY - all categories (USD)
A2: Prepared 2026-08-27 from Google Drive source files. DRAFT - for internal planning and counsel review only. Not a solicitation.
A4: Category | B4: Units | C4: Quick Sale (7-21d) | D4: Mid (30-45d) | E4: Slow / Retail (60-90d+) | F4: Status / Data gaps
A5: Slabs & tiles (porcelain/quartz/marble) | B5: =Slabs!E121 | C5: =Slabs!M121 | D5: =Slabs!N121 | E5: =Slabs!O121 | F5: Pcs per Jan-2025 list; verify current location & counts
A6: Forklifts & warehouse equipment | B6: =Equipment!E27 | C6: =SUMPRODUCT((Equipment!H4:H26="Yes")*Equipment!E4:E26*Equipment!J4:J26) | D6: =Equipment!M27 | E6: =SUMPRODUCT((Equipment!H4:H26="Yes")*Equipment!E4:E26*Equipment!L4:L26) | F6: On-hand rows only (May 2026 file); confirm hours/condition
A7: Appliances (luxury + mainstream) | B7: =Appliances!F43 | C7: =Appliances!J43 | D7: =Appliances!K43 | E7: =Appliances!L43 | F7: MSRP-based tiers; mainstream rows have researched asks in Notes
A8: Furniture / mattresses / displays | B8: TBD | C8: TBD | D8: TBD | E8: TBD | F8: Physical count required - Zoho stock shows zero for most SKUs
A9: Ausavina stone equipment (new stock) | B9: TBD | C9: TBD | D9: TBD | E9: TBD | F9: Use Ausavina US price list Apr-2025 as 'Slow'; count stock Sunday
A10: Mining licenses (13 sites, Turkiye) | B10: 13 | C10: n/a | D10: n/a | E10: n/a | F10: Not priced - teaser/NDA/data-room process; verify license fees paid
A11: TOTAL (priced categories) | C11: =SUM(C5:C7) | D11: =SUM(D5:D7) | E11: =SUM(E5:E7)
A13: LEGAL: Seller of record is Milhurst Mills (inventory sold to Milhurst in 2025); principal acts as its authorized sales agent. Principal is in Chapter 11
A14: (In re Cakmak, 26-11521-VFP, D.N.J.): signed agency agreement + counsel clearance (Zazella & Singer) required before any offer; all proceeds to Milhurst's account;
A15: agent compensation disclosed in MORs. Mining licenses are Ultima Ltd. Sti. property - NOT part of the Milhurst mandate. See SALES_PLAN_30_DAYS.md.

Sheet Slabs
A1: PORCELAIN / QUARTZ / MARBLE SLAB INVENTORY (BZ International Trade LLC records)
A3: Category | B3: Product | C3: Origin | D3: Size | E3: Pcs | F3: UnitCost_Actual | G3: ListA_Jan2025 | H3: ListB_Jun2025 | I3: Notes | J3: Quick Sale $/pc | K3: Mid $/pc | L3: Slow $/pc | M3: Total @ Quick | N3: Total @ Mid | O3: Total @ Slow
A4: Porcelain 5mm | B4: CALACATA PULIDO | C4: SPAIN | D4: 260X120X5 | E4: 52 | G4: 158 | H4: 290 | J4: =IF(F4<>"",F4*Assumptions!$B$4,"") | K4: =IF(F4<>"",F4,"") | L4: =IF(G4<>"",G4,F4) | M4: =IF(E4<>"",E4*J4,"") | N4: =IF(E4<>"",E4*K4,"") | O4: =IF(E4<>"",E4*L4,"")
A5: Porcelain 5mm | B5: CORINTO PULIDO | C5: SPAIN | D5: 260X120X5 | E5: 39 | G5: 158 | H5: 290 | J5: =IF(F5<>"",F5*Assumptions!$B$4,"") | K5: =IF(F5<>"",F5,"") | L5: =IF(G5<>"",G5,F5) | M5: =IF(E5<>"",E5*J5,"") | N5: =IF(E5<>"",E5*K5,"") | O5: =IF(E5<>"",E5*L5,"")
A6: Porcelain 5mm | B6: NERO ARDI | C6: SPAIN | D6: 260X120X5 | E6: 13 | G6: 158 | H6: 290 | J6: =IF(F6<>"",F6*Assumptions!$B$4,"") | K6: =IF(F6<>"",F6,"") | L6: =IF(G6<>"",G6,F6) | M6: =IF(E6<>"",E6*J6,"") | N6: =IF(E6<>"",E6*K6,"") | O6: =IF(E6<>"",E6*L6,"")
A7: Porcelain 5mm | B7: CARRARA NATURAL | C7: SPAIN | D7: 260X120X5 | E7: 13 | G7: 158 | H7: 290 | J7: =IF(F7<>"",F7*Assumptions!$B$4,"") | K7: =IF(F7<>"",F7,"") | L7: =IF(G7<>"",G7,F7) | M7: =IF(E7<>"",E7*J7,"") | N7: =IF(E7<>"",E7*K7,"") | O7: =IF(E7<>"",E7*L7,"")
A8: Porcelain 5mm | B8: ICEBERG | C8: SPAIN | D8: 260X120X5 | E8: 26 | G8: 158 | H8: 290 | J8: =IF(F8<>"",F8*Assumptions!$B$4,"") | K8: =IF(F8<>"",F8,"") | L8: =IF(G8<>"",G8,F8) | M8: =IF(E8<>"",E8*J8,"") | N8: =IF(E8<>"",E8*K8,"") | O8: =IF(E8<>"",E8*L8,"")
A9: Porcelain 5mm | B9: CARRARA GLOSSY | C9: SPAIN | D9: 260X120X5 | E9: 26 | G9: 158 | H9: 290 | J9: =IF(F9<>"",F9*Assumptions!$B$4,"") | K9: =IF(F9<>"",F9,"") | L9: =IF(G9<>"",G9,F9) | M9: =IF(E9<>"",E9*J9,"") | N9: =IF(E9<>"",E9*K9,"") | O9: =IF(E9<>"",E9*L9,"")
A10: Porcelain 5mm | B10: MARQUINA PLUDO | C10: SPAIN | D10: 260X120X5 | E10: 6 | G10: 158 | H10: 290 | J10: =IF(F10<>"",F10*Assumptions!$B$4,"") | K10: =IF(F10<>"",F10,"") | L10: =IF(G10<>"",G10,F10) | M10: =IF(E10<>"",E10*J10,"") | N10: =IF(E10<>"",E10*K10,"") | O10: =IF(E10<>"",E10*L10,"")
A11: Porcelain 5mm | B11: DISTRITO IRON | C11: SPAIN | D11: 260X120X5 | E11: 12 | G11: 158 | H11: 290 | J11: =IF(F11<>"",F11*Assumptions!$B$4,"") | K11: =IF(F11<>"",F11,"") | L11: =IF(G11<>"",G11,F11) | M11: =IF(E11<>"",E11*J11,"") | N11: =IF(E11<>"",E11*K11,"") | O11: =IF(E11<>"",E11*L11,"")
A12: Porcelain 5mm | B12: DISTRITO ALU | C12: SPAIN | D12: 260X120X5 | E12: 13 | G12: 158 | H12: 290 | J12: =IF(F12<>"",F12*Assumptions!$B$4,"") | K12: =IF(F12<>"",F12,"") | L12: =IF(G12<>"",G12,F12) | M12: =IF(E12<>"",E12*J12,"") | N12: =IF(E12<>"",E12*K12,"") | O12: =IF(E12<>"",E12*L12,"")
A13: Porcelain 5mm | B13: TACO PALADIO | C13: SPAIN | D13: 260X120X5 | E13: 6 | G13: 158 | H13: 290 | J13: =IF(F13<>"",F13*Assumptions!$B$4,"") | K13: =IF(F13<>"",F13,"") | L13: =IF(G13<>"",G13,F13) | M13: =IF(E13<>"",E13*J13,"") | N13: =IF(E13<>"",E13*K13,"") | O13: =IF(E13<>"",E13*L13,"")
A14: Porcelain 5mm | B14: WHITE GLOSSY | C14: SPAIN | D14: 260X120X5 | E14: 6 | G14: 158 | H14: 290 | J14: =IF(F14<>"",F14*Assumptions!$B$4,"") | K14: =IF(F14<>"",F14,"") | L14: =IF(G14<>"",G14,F14) | M14: =IF(E14<>"",E14*J14,"") | N14: =IF(E14<>"",E14*K14,"") | O14: =IF(E14<>"",E14*L14,"")
A15: Porcelain 5mm | B15: WHITE NAT | C15: SPAIN | D15: 260X120X5 | E15: 7 | G15: 158 | H15: 290 | J15: =IF(F15<>"",F15*Assumptions!$B$4,"") | K15: =IF(F15<>"",F15,"") | L15: =IF(G15<>"",G15,F15) | M15: =IF(E15<>"",E15*J15,"") | N15: =IF(E15<>"",E15*K15,"") | O15: =IF(E15<>"",E15*L15,"")
... A53: Porcelain 9mm | B53: CALCUTTA BORGHINI | C53: INDIA | D53: 1200X2400X9 | E53: 216 | G53: 62 | H53: 160 | J53: =IF(F53<>"",F53*Assumptions!$B$4,"") | K53: =IF(F53<>"",F53,"") | L53: =IF(G53<>"",G53,F53) | M53: =IF(E53<>"",E53*J53,"") | N53: =IF(E53<>"",E53*K53,"") | O53: =IF(E53<>"",E53*L53,"")
A54: Quartz 30mm | B54: 8064 W | C54: VIETNAM | D54: 3200X1600X30 | E54: 20 | F54: 481.28 | G54: 589 | H54: 550 | I54: Purchase cost from BZ Zoho item export | J54: =IF(F54<>"",F54*Assumptions!$B$4,"") | K54: =IF(F54<>"",F54,"") | L54: =IF(G54<>"",G54,F54) | M54: =IF(E54<>"",E54*J54,"") | N54: =IF(E54<>"",E54*K54,"") | O54: =IF(E54<>"",E54*L54,"")
A55: Quartz 30mm | B55: 8038 W | C55: VIETNAM | D55: 3200X1600X30 | E55: 20 | F55: 481.28 | G55: 589 | H55: 550 | J55: =IF(F55<>"",F55*Assumptions!$B$4,"") | K55: =IF(F55<>"",F55,"") | L55: =IF(G55<>"",G55,F55) | M55: =IF(E55<>"",E55*J55,"") | N55: =IF(E55<>"",E55*K55,"") | O55: =IF(E55<>"",E55*L55,"")
A56: Quartz 30mm | B56: 8098 W | C56: VIETNAM | D56: 3200X1600X30 | E56: 13 | F56: 481.28 | G56: 589 | H56: 550 | J56: =IF(F56<>"",F56*Assumptions!$B$4,"") | K56: =IF(F56<>"",F56,"") | L56: =IF(G56<>"",G56,F56) | M56: =IF(E56<>"",E56*J56,"") | N56: =IF(E56<>"",E56*K56,"") | O56: =IF(E56<>"",E56*L56,"")
A57: Quartz 30mm | B57: 9030 W | C57: VIETNAM | D57: 3200X1600X30 | E57: 5 | F57: 481.28 | G57: 589 | H57: 550 | J57: =IF(F57<>"",F57*Assumptions!$B$4,"") | K57: =IF(F57<>"",F57,"") | L57: =IF(G57<>"",G57,F57) | M57: =IF(E57<>"",E57*J57,"") | N57: =IF(E57<>"",E57*K57,"") | O57: =IF(E57<>"",E57*L57,"")
A58: Quartz 30mm | B58: 8039 W | C58: VIETNAM | D58: 3200X1600X30 | E58: 20 | F58: 481.28 | G58: 589 | H58: 550 | J58: =IF(F58<>"",F58*Assumptions!$B$4,"") | K58: =IF(F58<>"",F58,"") | L58: =IF(G58<>"",G58,F58) | M58: =IF(E58<>"",E58*J58,"") | N58: =IF(E58<>"",E58*K58,"") | O58: =IF(E58<>"",E58*L58,"")
A59: Quartz 30mm | B59: 8126 W | C59: VIETNAM | D59: 3200X1600X30 | E59: 10 | F59: 481.28 | G59: 589 | H59: 550 | J59: =IF(F59<>"",F59*Assumptions!$B$4,"") | K59: =IF(F59<>"",F59,"") | L59: =IF(G59<>"",G59,F59) | M59: =IF(E59<>"",E59*J59,"") | N59: =IF(E59<>"",E59*K59,"") | O59: =IF(E59<>"",E59*L59,"")
A60: Quartz 30mm | B60: KA9708 | C60: VIETNAM | D60: 3200X1600X30 | E60: 35 | F60: 481.28 | G60: 589 | H60: 550 | J60: =IF(F60<>"",F60*Assumptions!$B$4,"") | K60: =IF(F60<>"",F60,"") | L60: =IF(G60<>"",G60,F60) | M60: =IF(E60<>"",E60*J60,"") | N60: =IF(E60<>"",E60*K60,"") | O60: =IF(E60<>"",E60*L60,"")
A61: Quartz 30mm | B61: KA9705 | C61: VIETNAM | D61: 3200X1600X30 | E61: 34 | F61: 481.28 | G61: 589 | H61: 550 | J61: =IF(F61<>"",F61*Assumptions!$B$4,"") | K61: =IF(F61<>"",F61,"") | L61: =IF(G61<>"",G61,F61) | M61: =IF(E61<>"",E61*J61,"") | N61: =IF(E61<>"",E61*K61,"") | O61: =IF(E61<>"",E61*L61,"")
A62: Quartz 30mm | B62: 9020 W | C62: VIETNAM | D62: 3200X1600X30 | E62: 19 | F62: 481.28 | G62: 589 | H62: 550 | J62: =IF(F62<>"",F62*Assumptions!$B$4,"") | K62: =IF(F62<>"",F62,"") | L62: =IF(G62<>"",G62,F62) | M62: =IF(E62<>"",E62*J62,"") | N62: =IF(E62<>"",E62*K62,"") | O62: =IF(E62<>"",E62*L62,"")
A63: Quartz 30mm | B63: 8083 W | C63: VIETNAM | D63: 3200X1600X30 | E63: 16 | F63: 481.28 | G63: 589 | H63: 550 | J63: =IF(F63<>"",F63*Assumptions!$B$4,"") | K63: =IF(F63<>"",F63,"") | L63: =IF(G63<>"",G63,F63) | M63: =IF(E63<>"",E63*J63,"") | N63: =IF(E63<>"",E63*K63,"") | O63: =IF(E63<>"",E63*L63,"")
A64: Quartz 30mm | B64: 8022 W | C64: VIETNAM | D64: 3200X1600X30 | E64: 14 | F64: 481.28 | G64: 589 | H64: 550 | J64: =IF(F64<>"",F64*Assumptions!$B$4,"") | K64: =IF(F64<>"",F64,"") | L64: =IF(G64<>"",G64,F64) | M64: =IF(E64<>"",E64*J64,"") | N64: =IF(E64<>"",E64*K64,"") | O64: =IF(E64<>"",E64*L64,"")
A65: Quartz 30mm | B65: KVA9928 | C65: VIETNAM | D65: 3200X1600X30 | E65: 1 | F65: 481.28 | G65: 589 | H65: 550 | J65: =IF(F65<>"",F65*Assumptions!$B$4,"") | K65: =IF(F65<>"",F65,"") | L65: =IF(G65<>"",G65,F65) | M65: =IF(E65<>"",E65*J65,"") | N65: =IF(E65<>"",E65*K65,"") | O65: =IF(E65<>"",E65*L65,"")
A66: Porcelain 5mm | B66: SUPER WHITE GLOSSY | C66: ITALY | D66: 2780X1200X5 | E66: 44 | G66: 164 | H66: 290 | J66: =IF(F66<>"",F66*Assumptions!$B$4,"") | K66: =IF(F66<>"",F66,"") | L66: =IF(G66<>"",G66,F66) | M66: =IF(E66<>"",E66*J66,"") | N66: =IF(E66<>"",E66*K66,"") | O66: =IF(E66<>"",E66*L66,"")
A67: Porcelain 5mm | B67: TAJ MAHAL GLOSSY | C67: ITALY | D67: 2780X1200X5 | E67: 36 | G67: 164 | H67: 290 | J67: =IF(F67<>"",F67*Assumptions!$B$4,"") | K67: =IF(F67<>"",F67,"") | L67: =IF(G67<>"",G67,F67) | M67: =IF(E67<>"",E67*J67,"") | N67: =IF(E67<>"",E67*K67,"") | O67: =IF(E67<>"",E67*L67,"")
A68: Porcelain 5mm | B68: CAPRAIA GLOSSY | C68: ITALY | D68: 2780X1200X5 | E68: 32 | G68: 164 | H68: 290 | J68: =IF(F68<>"",F68*Assumptions!$B$4,"") | K68: =IF(F68<>"",F68,"") | L68: =IF(G68<>"",G68,F68) | M68: =IF(E68<>"",E68*J68,"") | N68: =IF(E68<>"",E68*K68,"") | O68: =IF(E68<>"",E68*L68,"")
A69: Porcelain 5mm | B69: CAL MACCHIA GLOSSY | C69: ITALY | D69: 2780X1200X5 | E69: 32 | G69: 164 | H69: 290 | J69: =IF(F69<>"",F69*Assumptions!$B$4,"") | K69: =IF(F69<>"",F69,"") | L69: =IF(G69<>"",G69,F69) | M69: =IF(E69<>"",E69*J69,"") | N69: =IF(E69<>"",E69*K69,"") | O69: =IF(E69<>"",E69*L69,"")
A70: Porcelain 5mm | B70: STATUARIO GLOSSY | C70: ITALY | D70: 2780X1200X5 | E70: 37 | G70: 164 | H70: 290 | J70: =IF(F70<>"",F70*Assumptions!$B$4,"") | K70: =IF(F70<>"",F70,"") | L70: =IF(G70<>"",G70,F70) | M70: =IF(E70<>"",E70*J70,"") | N70: =IF(E70<>"",E70*K70,"") | O70: =IF(E70<>"",E70*L70,"")
A71: Porcelain 5mm | B71: CAPRAIA NAT | C71: ITALY | D71: 2780X1200X5 | E71: 44 | G71: 164 | H71: 290 | J71: =IF(F71<>"",F71*Assumptions!$B$4,"") | K71: =IF(F71<>"",F71,"") | L71: =IF(G71<>"",G71,F71) | M71: =IF(E71<>"",E71*J71,"") | N71: =IF(E71<>"",E71*K71,"") | O71: =IF(E71<>"",E71*L71,"")
A72: Porcelain 5mm | B72: FIO DI BO GLOSSY | C72: ITALY | D72: 2780X1200X5 | E72: 44 | G72: 164 | H72: 290 | J72: =IF(F72<>"",F72*Assumptions!$B$4,"") | K72: =IF(F72<>"",F72,"") | L72: =IF(G72<>"",G72,F72) | M72: =IF(E72<>"",E72*J72,"") | N72: =IF(E72<>"",E72*K72,"") | O72: =IF(E72<>"",E72*L72,"")
A73: Porcelain 5mm | B73: CAL LIGHT HAN RET | C73: ITALY | D73: 2780X1200X5 | E73: 44 | G73: 164 | H73: 290 | J73: =IF(F73<>"",F73*Assumptions!$B$4,"") | K73: =IF(F73<>"",F73,"") | L73: =IF(G73<>"",G73,F73) | M73: =IF(E73<>"",E73*J73,"") | N73: =IF(E73<>"",E73*K73,"") | O73: =IF(E73<>"",E73*L73,"")
A74: Porcelain 5mm | B74: CALACATA WHITE GLOSSY | C74: ITALY | D74: 2780X1200X5 | E74: 44 | G74: 164 | H74: 290 | J74: =IF(F74<>"",F74*Assumptions!$B$4,"") | K74: =IF(F74<>"",F74,"") | L74: =IF(G74<>"",G74,F74) | M74: =IF(E74<>"",E74*J74,"") | N74: =IF(E74<>"",E74*K74,"") | O74: =IF(E74<>"",E74*L74,"")
A75: Porcelain 5mm | B75: CAL LIGHT GLOSSY | C75: ITALY | D75: 2780X1200X5 | E75: 44 | G75: 164 | H75: 290 | J75: =IF(F75<>"",F75*Assumptions!$B$4,"") | K75: =IF(F75<>"",F75,"") | L75: =IF(G75<>"",G75,F75) | M75: =IF(E75<>"",E75*J75,"") | N75: =IF(E75<>"",E75*K75,"") | O75: =IF(E75<>"",E75*L75,"")
A76: Porcelain 5mm | B76: OLINCALN HAN RET | C76: ITALY | D76: 2780X1200X5 | E76: 44 | G76: 164 | H76: 290 | J76: =IF(F76<>"",F76*Assumptions!$B$4,"") | K76: =IF(F76<>"",F76,"") | L76: =IF(G76<>"",G76,F76) | M76: =IF(E76<>"",E76*J76,"") | N76: =IF(E76<>"",E76*K76,"") | O76: =IF(E76<>"",E76*L76,"")
A77: Porcelain 5mm | B77: PIETRO GREYY NAT | C77: ITALY | D77: 2780X1200X5 | E77: 132 | G77: 164 | H77: 290 | J77: =IF(F77<>"",F77*Assumptions!$B$4,"") | K77: =IF(F77<>"",F77,"") | L77: =IF(G77<>"",G77,F77) | M77: =IF(E77<>"",E77*J77,"") | N77: =IF(E77<>"",E77*K77,"") | O77: =IF(E77<>"",E77*L77,"")
... A114: Quartz 30mm (Quartzforms) | B114: BLONE BREEZE | C114: GERMANY | D114: 3050X1400X30 | E114: 3 | G114: 1050 | H114: 1141 | J114: =IF(F114<>"",F114*Assumptions!$B$4,"") | K114: =IF(F114<>"",F114,"") | L114: =IF(G114<>"",G114,F114) | M114: =IF(E114<>"",E114*J114,"") | N114: =IF(E114<>"",E114*K114,"") | O114: =IF(E114<>"",E114*L114,"")
...

Sheet Equipment
A1: FORKLIFT & WAREHOUSE EQUIPMENT (BZ International Trade LLC - 2024 stock summary; On-hand flag = May 2026 file)
A3: Category | B3: Item | C3: Brand | D3: Vendor | E3: Qty_2024 | F3: UnitCost | G3: SalesListPrice | H3: OnHand_May2026 | I3: Notes | J3: Quick $/unit | K3: Mid $/unit | L3: Slow $/unit | M3: Line Total @ Mid (on-hand only)
A4: Forklift Diesel/LPG | B4: LK LG30GLT Forklift (3.0t gas/LPG) | C4: LONKING | D4: LONKING INTERNATIONAL | E4: 1 | F4: 22515 | G4: 29890 | H4: No | I4: Not in May 2026 file - verify if sold | J4: =IF(F4<>"",F4*Assumptions!$B$7,"") | K4: =IF(F4<>"",F4*Assumptions!$B$8,"") | L4: =IF(G4<>"",G4,IF(F4<>"",F4*0.95,"")) | M4: =IF(H4="Yes",E4*K4,0)
A5: Forklift Diesel/LPG | B5: LK LG35GLT Forklift (3.5t gas/LPG) | C5: LONKING | D5: LONKING INTERNATIONAL | E5: 1 | F5: 24700 | G5: 31890 | H5: No | I5: Not in May 2026 file - verify if sold | J5: =IF(F5<>"",F5*Assumptions!$B$7,"") | K5: =IF(F5<>"",F5*Assumptions!$B$8,"") | L5: =IF(G5<>"",G5,IF(F5<>"",F5*0.95,"")) | M5: =IF(H5="Yes",E5*K5,0)
A6: Forklift Electric | B6: LK LG30B Forklift (3.0t electric) | C6: LONKING | D6: LONKING INTERNATIONAL | E6: 1 | F6: 25800 | G6: 34690 | H6: No | I6: Not in May 2026 file - verify if sold | J6: =IF(F6<>"",F6*Assumptions!$B$7,"") | K6: =IF(F6<>"",F6*Assumptions!$B$8,"") | L6: =IF(G6<>"",G6,IF(F6<>"",F6*0.95,"")) | M6: =IF(H6="Yes",E6*K6,0)
A7: Forklift Electric | B7: LK LG35B Forklift (3.5t electric) | C7: LONKING | D7: LONKING INTERNATIONAL | E7: 1 | F7: 26600 | G7: 35690 | H7: No | I7: Not in May 2026 file - verify if sold | J7: =IF(F7<>"",F7*Assumptions!$B$7,"") | K7: =IF(F7<>"",F7*Assumptions!$B$8,"") | L7: =IF(G7<>"",G7,IF(F7<>"",F7*0.95,"")) | M7: =IF(H7="Yes",E7*K7,0)
A8: Forklift Electric | B8: LK LG50B Forklift (5.0t electric) | C8: LONKING | D8: LONKING INTERNATIONAL | E8: 1 | F8: 38700 | G8: 58690 | H8: No | I8: Not in May 2026 file - verify if sold | J8: =IF(F8<>"",F8*Assumptions!$B$7,"") | K8: =IF(F8<>"",F8*Assumptions!$B$8,"") | L8: =IF(G8<>"",G8,IF(F8<>"",F8*0.95,"")) | M8: =IF(H8="Yes",E8*K8,0)
A9: Pallet Truck | B9: ZW XPA20 Electric Pallet Truck | C9: ZOWELL | D9: SUZHOU PIONEER MATERIAL | E9: 3 | F9: 6800 | G9: 8790 | H9: Yes | J9: =IF(F9<>"",F9*Assumptions!$B$7,"") | K9: =IF(F9<>"",F9*Assumptions!$B$8,"") | L9: =IF(G9<>"",G9,IF(F9<>"",F9*0.95,"")) | M9: =IF(H9="Yes",E9*K9,0)
A10: Pallet Truck | B10: ZW XPA25 Electric Pallet Truck | C10: ZOWELL | D10: SUZHOU PIONEER MATERIAL | E10: 3 | F10: 7100 | G10: 9290 | H10: Yes | J10: =IF(F10<>"",F10*Assumptions!$B$7,"") | K10: =IF(F10<>"",F10*Assumptions!$B$8,"") | L10: =IF(G10<>"",G10,IF(F10<>"",F10*0.95,"")) | M10: =IF(H10="Yes",E10*K10,0)
A11: Towing Tractor | B11: ZW XTE50 Electric Towing Tractor | C11: ZOWELL | D11: SUZHOU PIONEER MATERIAL | E11: 2 | F11: 11500 | G11: 14890 | H11: Yes | J11: =IF(F11<>"",F11*Assumptions!$B$7,"") | K11: =IF(F11<>"",F11*Assumptions!$B$8,"") | L11: =IF(G11<>"",G11,IF(F11<>"",F11*0.95,"")) | M11: =IF(H11="Yes",E11*K11,0)
A12: Forklift Diesel | B12: HU CPCD30 Forklift (3.0t diesel) | C12: HUAYA | D12: XINGTAI HUAYA MACHINE | E12: 1 | F12: 23400 | H12: No | I12: Not in May 2026 file - verify if sold | J12: =IF(F12<>"",F12*Assumptions!$B$7,"") | K12: =IF(F12<>"",F12*Assumptions!$B$8,"") | L12: =IF(G12<>"",G12,IF(F12<>"",F12*0.95,"")) | M12: =IF(H12="Yes",E12*K12,0)
A13: Forklift Diesel | B13: HU CPCD35 Forklift (3.5t diesel) | C13: HUAYA | D13: XINGTAI HUAYA MACHINE | E13: 2 | F13: 24400 | H13: Yes | J13: =IF(F13<>"",F13*Assumptions!$B$7,"") | K13: =IF(F13<>"",F13*Assumptions!$B$8,"") | L13: =IF(G13<>"",G13,IF(F13<>"",F13*0.95,"")) | M13: =IF(H13="Yes",E13*K13,0)
A14: Forklift LPG | B14: HU LPG35 Forklift (3.5t LPG) | C14: HUAYA | D14: XINGTAI HUAYA MACHINE | E14: 2 | F14: 27400 | H14: No | I14: Not in May 2026 file - verify if sold | J14: =IF(F14<>"",F14*Assumptions!$B$7,"") | K14: =IF(F14<>"",F14*Assumptions!$B$8,"") | L14: =IF(G14<>"",G14,IF(F14<>"",F14*0.95,"")) | M14: =IF(H14="Yes",E14*K14,0)
A15: VNA Truck | B15: ZW VDA116 Electric VNA Truck (rotating forks + camera) | C15: ZOWELL | D15: SUZHOU PIONEER MATERIAL | E15: 2 | F15: 53750 | H15: No | I15: High-value unit - verify status | J15: =IF(F15<>"",F15*Assumptions!$B$7,"") | K15: =IF(F15<>"",F15*Assumptions!$B$8,"") | L15: =IF(G15<>"",G15,IF(F15<>"",F15*0.95,"")) | M15: =IF(H15="Yes",E15*K15,0)
A16: Stacker | B16: ZW XEB15 Electric Stacker | C16: ZOWELL | D16: SUZHOU PIONEER MATERIAL | E16: 1 | F16: 7900 | H16: Yes | J16: =IF(F16<>"",F16*Assumptions!$B$7,"") | K16: =IF(F16<>"",F16*Assumptions!$B$8,"") | L16: =IF(G16<>"",G16,IF(F16<>"",F16*0.95,"")) | M16: =IF(H16="Yes",E16*K16,0)
A17: Stacker | B17: ZW XEA12 Electric Stacker | C17: ZOWELL | D17: SUZHOU PIONEER MATERIAL | E17: 3 | F17: 5500 | H17: Yes | J17: =IF(F17<>"",F17*Assumptions!$B$7,"") | K17: =IF(F17<>"",F17*Assumptions!$B$8,"") | L17: =IF(G17<>"",G17,IF(F17<>"",F17*0.95,"")) | M17: =IF(H17="Yes",E17*K17,0)
A18: Stacker | B18: ZW XEK15 Electric Stacker | C18: ZOWELL | D18: SUZHOU PIONEER MATERIAL | E18: 1 | F18: 11800 | H18: Yes | J18: =IF(F18<>"",F18*Assumptions!$B$7,"") | K18: =IF(F18<>"",F18*Assumptions!$B$8,"") | L18: =IF(G18<>"",G18,IF(F18<>"",F18*0.95,"")) | M18: =IF(H18="Yes",E18*K18,0)
A19: Reach Truck | B19: ZW RRE115 Electric Double-Deep Reach Truck | C19: ZOWELL | D19: SUZHOU PIONEER MATERIAL | E19: 1 | F19: 47400 | H19: No | I19: High-value unit - verify status | J19: =IF(F19<>"",F19*Assumptions!$B$7,"") | K19: =IF(F19<>"",F19*Assumptions!$B$8,"") | L19: =IF(G19<>"",G19,IF(F19<>"",F19*0.95,"")) | M19: =IF(H19="Yes",E19*K19,0)
A20: Reach Truck | B20: ZW FRC15 Electric Reach Truck | C20: ZOWELL | D20: SUZHOU PIONEER MATERIAL | E20: 2 | F20: 15150 | H20: Yes | J20: =IF(F20<>"",F20*Assumptions!$B$7,"") | K20: =IF(F20<>"",F20*Assumptions!$B$8,"") | L20: =IF(G20<>"",G20,IF(F20<>"",F20*0.95,"")) | M20: =IF(H20="Yes",E20*K20,0)
A21: Stacker | B21: ZW XE20 Electric Stacker | C21: ZOWELL | D21: SUZHOU PIONEER MATERIAL | E21: 2 | F21: 9100 | H21: Yes | J21: =IF(F21<>"",F21*Assumptions!$B$7,"") | K21: =IF(F21<>"",F21*Assumptions!$B$8,"") | L21: =IF(G21<>"",G21,IF(F21<>"",F21*0.95,"")) | M21: =IF(H21="Yes",E21*K21,0)
A22: Stacker | B22: ZW XEBK15 Electric Stacker | C22: ZOWELL | D22: SUZHOU PIONEER MATERIAL | E22: 2 | F22: 10700 | H22: Yes | J22: =IF(F22<>"",F22*Assumptions!$B$7,"") | K22: =IF(F22<>"",F22*Assumptions!$B$8,"") | L22: =IF(G22<>"",G22,IF(F22<>"",F22*0.95,"")) | M22: =IF(H22="Yes",E22*K22,0)
A23: Forklift IC | B23: RY G30 Forklift Truck (3.0t IC) | C23: RY | D23: ROYAL FORKLIFT SUZHOU | E23: 2 | F23: 28700 | H23: No | I23: Not in May 2026 file - verify if sold | J23: =IF(F23<>"",F23*Assumptions!$B$7,"") | K23: =IF(F23<>"",F23*Assumptions!$B$8,"") | L23: =IF(G23<>"",G23,IF(F23<>"",F23*0.95,"")) | M23: =IF(H23="Yes",E23*K23,0)
A24: Forklift Electric | B24: RY E20e Electric Forklift (3-wheel dual drive) | C24: RY | D24: ROYAL FORKLIFT SUZHOU | E24: 1 | F24: 28700 | H24: No | I24: Not in May 2026 file - verify if sold | J24: =IF(F24<>"",F24*Assumptions!$B$7,"") | K24: =IF(F24<>"",F24*Assumptions!$B$8,"") | L24: =IF(G24<>"",G24,IF(F24<>"",F24*0.95,"")) | M24: =IF(H24="Yes",E24*K24,0)
A25: Forklift Electric | B25: RY E30Q Electric Forklift | C25: RY | D25: ROYAL FORKLIFT SUZHOU | E25: 1 | F25: 31350 | H25: Yes | J25: =IF(F25<>"",F25*Assumptions!$B$7,"") | K25: =IF(F25<>"",F25*Assumptions!$B$8,"") | L25: =IF(G25<>"",G25,IF(F25<>"",F25*0.95,"")) | M25: =IF(H25="Yes",E25*K25,0)
A26: Forklift Electric | B26: RY E35Q Electric Forklift | C26: RY | D26: ROYAL FORKLIFT SUZHOU | E26: 1 | F26: 34700 | H26: No | I26: Not in May 2026 file - verify if sold | J26: =IF(F26<>"",F26*Assumptions!$B$7,"") | K26: =IF(F26<>"",F26*Assumptions!$B$8,"") | L26: =IF(G26<>"",G26,IF(F26<>"",F26*0.95,"")) | M26: =IF(H26="Yes",E26*K26,0)
A27: TOTALS | E27: =SUM(E4:E26) | M27: =SUM(M4:M26)
A28: 2024 acquisition cost (all units): | E28: =SUMPRODUCT(E4:E26,F4:F26)
A29: Note: 'On-hand May 2026' = item appears in the May 2026 inventory file. Quantities need physical verification before offers go out.

Sheet Appliances
A1: APPLIANCE INVENTORY (Luxury: Gaggenau/Miele/Thermador/Bosch - new, several boxed. Mainstream: Milhurst list)
A3: Group | B3: Brand | C3: Model | D3: Description | E3: Qty | F3: UnitCost | G3: MSRP | H3: VerifiedRetail | I3: Notes | J3: Quick $ | K3: Mid $ | L3: Slow $
A4: Luxury | B4: GAGGENAU | C4: BS470612 | D4: 400 Series 24" Combi Steam Oven | E4: 1 | F4: 5240 | G4: 9899 | H4: 9899 | I4: Price hidden by dealers; MSRP retained | J4: =IF(G4<>"",G4*Assumptions!$B$11,"") | K4: =IF(G4<>"",G4*Assumptions!$B$12,"") | L4: =IF(G4<>"",G4*Assumptions!$B$13,"")
A5: Luxury | B5: GAGGENAU | C5: BO480613 | D5: Oven 30" 400 Series SS Glass L | E5: 1 | F5: 5240 | G5: 9899 | H5: 9899 | I5: Boxed | J5: =IF(G5<>"",G5*Assumptions!$B$11,"") | K5: =IF(G5<>"",G5*Assumptions!$B$12,"") | L5: =IF(G5<>"",G5*Assumptions!$B$13,"")
A6: Luxury | B6: GAGGENAU | C6: AL400792 | D6: 400 Series Telescopic Ventilation | E6: 1 | F6: 2792 | G6: 5399 | H6: 5399 | I6: Retailer sale price verified | J6: =IF(G6<>"",G6*Assumptions!$B$11,"") | K6: =IF(G6<>"",G6*Assumptions!$B$12,"") | L6: =IF(G6<>"",G6*Assumptions!$B$13,"")
A7: Luxury | B7: GAGGENAU | C7: RC472705 | D7: Vario 400 Refrigerator 30" 2-Door | E7: 1 | F7: 7632 | G7: 12999 | H7: 12999 | J7: =IF(G7<>"",G7*Assumptions!$B$11,"") | K7: =IF(G7<>"",G7*Assumptions!$B$12,"") | L7: =IF(G7<>"",G7*Assumptions!$B$13,"")
A8: Luxury | B8: GAGGENAU | C8: WS463710-960 | D8: 24" Warming Drawer | E8: 1 | F8: 1492 | G8: 2699 | H8: 2699 | J8: =IF(G8<>"",G8*Assumptions!$B$11,"") | K8: =IF(G8<>"",G8*Assumptions!$B$12,"") | L8: =IF(G8<>"",G8*Assumptions!$B$13,"")
A9: Luxury | B9: GAGGENAU | C9: WS461710-960 | D9: 24" Warming Drawer | E9: 1 | F9: 1392 | G9: 2549 | H9: 2549 | J9: =IF(G9<>"",G9*Assumptions!$B$11,"") | K9: =IF(G9<>"",G9*Assumptions!$B$12,"") | L9: =IF(G9<>"",G9*Assumptions!$B$13,"")
A10: Luxury | B10: GAGGENAU | C10: BMP250710/1 | D10: Combi Oven 361 200 Series | E10: 1 | F10: 3216 | G10: 5849 | H10: 5849 | I10: Discontinued model | J10: =IF(G10<>"",G10*Assumptions!$B$11,"") | K10: =IF(G10<>"",G10*Assumptions!$B$12,"") | L10: =IF(G10<>"",G10*Assumptions!$B$13,"")
A11: Luxury | B11: GAGGENAU | C11: BS484612 | D11: 400 Series 30" Combi Steam Oven | E11: 1 | F11: 6936 | G11: 11699 | H11: 11699 | I11: Boxed | J11: =IF(G11<>"",G11*Assumptions!$B$11,"") | K11: =IF(G11<>"",G11*Assumptions!$B$12,"") | L11: =IF(G11<>"",G11*Assumptions!$B$13,"")
A12: Luxury | B12: GAGGENAU | C12: VI230620/02 | D12: 200 Series Vario Induction 12" | E12: 1 | F12: 1484 | G12: 2649 | H12: 2649 | J12: =IF(G12<>"",G12*Assumptions!$B$11,"") | K12: =IF(G12<>"",G12*Assumptions!$B$12,"") | L12: =IF(G12<>"",G12*Assumptions!$B$13,"")
A13: Luxury | B13: GAGGENAU | C13: VG231220CA | D13: 200 Series Vario Gas Wok Burner | E13: 1 | F13: 1872 | G13: 2999 | H13: 2999 | J13: =IF(G13<>"",G13*Assumptions!$B$11,"") | K13: =IF(G13<>"",G13*Assumptions!$B$12,"") | L13: =IF(G13<>"",G13*Assumptions!$B$13,"")
A14: Luxury | B14: GAGGENAU | C14: VG2322OCA | D14: 200 Series Vario 12" Gas 2-Burner | E14: 1 | F14: 1484 | G14: 2599 | H14: 2599 | I14: Model tag needs verification (likely VG232220CA) | J14: =IF(G14<>"",G14*Assumptions!$B$11,"") | K14: =IF(G14<>"",G14*Assumptions!$B$12,"") | L14: =IF(G14<>"",G14*Assumptions!$B$13,"")
A15: Luxury | B15: GAGGENAU | C15: CMP250711 | D15: Built-In Automatic Coffee Machine | E15: 1 | F15: 2592 | G15: 4899 | H15: 4899 | J15: =IF(G15<>"",G15*Assumptions!$B$11,"") | K15: =IF(G15<>"",G15*Assumptions!$B$12,"") | L15: =IF(G15<>"",G15*Assumptions!$B$13,"")
A16: Luxury | B16: GAGGENAU | C16: BO450612 | D16: 24" 400 Series SS/Glass R | E16: 1 | F16: 4528 | G16: 8149 | H16: 8149 | J16: =IF(G16<>"",G16*Assumptions!$B$11,"") | K16: =IF(G16<>"",G16*Assumptions!$B$12,"") | L16: =IF(G16<>"",G16*Assumptions!$B$13,"")
A17: Luxury | B17: GAGGENAU | C17: DF481701 | D17: Dishwasher Fully Integrated 60cm | E17: 1 | F17: 2292 | G17: 3899 | H17: 3899 | I17: Boxed | J17: =IF(G17<>"",G17*Assumptions!$B$11,"") | K17: =IF(G17<>"",G17*Assumptions!$B$12,"") | L17: =IF(G17<>"",G17*Assumptions!$B$13,"")
A18: Luxury | B18: MIELE | C18: KM6365 | D18: 30" Flush Mounted Induction Cooktop | E18: 1 | F18: 2125 | G18: 3499 | H18: 3499 | J18: =IF(G18<>"",G18*Assumptions!$B$11,"") | K18: =IF(G18<>"",G18*Assumptions!$B$12,"") | L18: =IF(G18<>"",G18*Assumptions!$B$13,"")
A19: Luxury | B19: MIELE | C19: DGC7840 | D19: 24" VitroLine Combi Steam | E19: 1 | F19: 3299 | G19: 5999 | H19: 5999 | J19: =IF(G19<>"",G19*Assumptions!$B$11,"") | K19: =IF(G19<>"",G19*Assumptions!$B$12,"") | L19: =IF(G19<>"",G19*Assumptions!$B$13,"")
A20: Luxury | B20: MIELE | C20: ESW6214 | D20: 24" PureLine Warming Drawer | E20: 1 | F20: 769 | G20: 1399 | H20: 1399 | J20: =IF(G20<>"",G20*Assumptions!$B$11,"") | K20: =IF(G20<>"",G20*Assumptions!$B$12,"") | L20: =IF(G20<>"",G20*Assumptions!$B$13,"")
A21: Luxury | B21: MIELE | C21: G 7176 SCVI | D21: AutoDos Dishwasher | E21: 1 | F21: 1059 | G21: 1849 | H21: 1849 | J21: =IF(G21<>"",G21*Assumptions!$B$11,"") | K21: =IF(G21<>"",G21*Assumptions!$B$12,"") | L21: =IF(G21<>"",G21*Assumptions!$B$13,"")
A22: Luxury | B22: MIELE | C22: HR 1953 2G | D22: 36" Dual Fuel Range M Touch M Pro Grill | E22: 1 | F22: 7849 | G22: 13099 | J22: =IF(G22<>"",G22*Assumptions!$B$11,"") | K22: =IF(G22<>"",G22*Assumptions!$B$12,"") | L22: =IF(G22<>"",G22*Assumptions!$B$13,"")
A23: Luxury | B23: MIELE | C23: K2602 VI | D23: 24" MasterCool Refrigerator Panel Ready | E23: 1 | F23: 5409 | G23: 9199 | J23: =IF(G23<>"",G23*Assumptions!$B$11,"") | K23: =IF(G23<>"",G23*Assumptions!$B$12,"") | L23: =IF(G23<>"",G23*Assumptions!$B$13,"")
A24: Luxury | B24: MIELE | C24: K 2802 VI | D24: 30" MasterCool Bottom RH Mount Panel Ready | E24: 1 | F24: 5896 | G24: 9699 | J24: =IF(G24<>"",G24*Assumptions!$B$11,"") | K24: =IF(G24<>"",G24*Assumptions!$B$12,"") | L24: =IF(G24<>"",G24*Assumptions!$B$13,"")
A25: Luxury | B25: MIELE | C25: KWT 2672 VIS | D25: 24" MasterCool Wine Unit Sommelier Panel Ready | E25: 1 | F25: 6754 | G25: 10599 | J25: =IF(G25<>"",G25*Assumptions!$B$11,"") | K25: =IF(G25<>"",G25*Assumptions!$B$12,"") | L25: =IF(G25<>"",G25*Assumptions!$B$13,"")
A26: Luxury | B26: MIELE | C26: H 7780 BP2 | D26: 30" ContourLine Double Oven M Touch | E26: 1 | F26: 7664 | G26: 11699 | J26: =IF(G26<>"",G26*Assumptions!$B$11,"") | K26: =IF(G26<>"",G26*Assumptions!$B$12,"") | L26: =IF(G26<>"",G26*Assumptions!$B$13,"")
A27: Luxury | B27: MIELE | C27: DA 6891 | D27: Miele Downdraft Hood 36" | E27: 1 | F27: 1895 | G27: 3399 | J27: =IF(G27<>"",G27*Assumptions!$B$11,"") | K27: =IF(G27<>"",G27*Assumptions!$B$12,"") | L27: =IF(G27<>"",G27*Assumptions!$B$13,"")
A28: Luxury | B28: MIELE | C28: CVA 7845 | D28: 24" VitroLine Coffee Plumbed M Touch | E28: 1 | F28: 3754 | G28: 6999 | J28: =IF(G28<>"",G28*Assumptions!$B$11,"") | K28: =IF(G28<>"",G28*Assumptions!$B$12,"") | L28: =IF(G28<>"",G28*Assumptions!$B$13,"")
A29: Luxury | B29: THERMADOR | C29: T36BT120NS | D29: Built-In Fridge Freezer | E29: 1 | F29: 7890 | G29: 13199 | I29: Boxed | J29: =IF(G29<>"",G29*Assumptions!$B$11,"") | K29: =IF(G29<>"",G29*Assumptions!$B$12,"") | L29: =IF(G29<>"",G29*Assumptions!$B$13,"")
A30: Luxury | B30: THERMADOR | C30: PRG304WH-8 | D30: Pro Harmony 30" Gas Range | E30: 1 | F30: 2960 | G30: 5699 | J30: =IF(G30<>"",G30*Assumptions!$B$11,"") | K30: =IF(G30<>"",G30*Assumptions!$B$12,"") | L30: =IF(G30<>"",G30*Assumptions!$B$13,"")
A31: Luxury | B31: THERMADOR | C31: HPCN36WS | D31: 36" Professional Chimney Hood | E31: 1 | F31: 1860 | G31: 3449 | J31: =IF(G31<>"",G31*Assumptions!$B$11,"") | K31: =IF(G31<>"",G31*Assumptions!$B$12,"") | L31: =IF(G31<>"",G31*Assumptions!$B$13,"")
A32: Luxury | B32: BOSCH | C32: SHX9PCM5N | D32: Pocket Handle 800 Dishwasher | E32: 1 | F32: 1078 | G32: 1999 | J32: =IF(G32<>"",G32*Assumptions!$B$11,"") | K32: =IF(G32<>"",G32*Assumptions!$B$12,"") | L32: =IF(G32<>"",G32*Assumptions!$B$13,"")
A33: Luxury | B33: BOSCH | C33: NITP660SUL | D33: Induction Cooktop Benchmark | E33: 1 | F33: 1849 | G33: 3599 | J33: =IF(G33<>"",G33*Assumptions!$B$11,"") | K33: =IF(G33<>"",G33*Assumptions!$B$12,"") | L33: =IF(G33<>"",G33*Assumptions!$B$13,"")
A34: Luxury | B34: BOSCH | C34: HBES453UC-03 | D34: 500 Series Electric Wall Oven | E34: 1 | F34: 1196 | G34: 2299 | J34: =IF(G34<>"",G34*Assumptions!$B$11,"") | K34: =IF(G34<>"",G34*Assumptions!$B$12,"") | L34: =IF(G34<>"",G34*Assumptions!$B$13,"")
A35: Luxury | B35: BOSCH | C35: HCG56651UC | D35: 500 Series Hood | E35: 1 | F35: 1196 | G35: 2299 | J35: =IF(G35<>"",G35*Assumptions!$B$11,"") | K35: =IF(G35<>"",G35*Assumptions!$B$12,"") | L35: =IF(G35<>"",G35*Assumptions!$B$13,"")
A36: Mainstream | B36: FRIGIDAIRE | C36: FRSS2323AS | D36: 22.3 cu.ft 33" Side-by-Side Refrigerator SS | E36: 1 | G36: 1399 | H36: 1099 | I36: Suggested ask 949 / wholesale 775 / floor 699 | J36: =IF(G36<>"",G36*Assumptions!$B$11,"") | K36: =IF(G36<>"",G36*Assumptions!$B$12,"") | L36: =IF(G36<>"",G36*Assumptions!$B$13,"")
A37: Mainstream | B37: FRIGIDAIRE | C37: FDPC4314AS | D37: 24" Front-Control Built-In Dishwasher SS | E37: 1 | G37: 599 | H37: 393 | I37: Suggested ask 329 / wholesale 259 / floor 225 | J37: =IF(G37<>"",G37*Assumptions!$B$11,"") | K37: =IF(G37<>"",G37*Assumptions!$B$12,"") | L37: =IF(G37<>"",G37*Assumptions!$B$13,"")
A38: Mainstream | B38: FRIGIDAIRE | C38: GMOS1962AF | D38: 1.9 cu.ft Over-the-Range Microwave SS | E38: 1 | G38: 529 | H38: 429 | I38: Suggested ask 329 / wholesale 249 / floor 225 | J38: =IF(G38<>"",G38*Assumptions!$B$11,"") | K38: =IF(G38<>"",G38*Assumptions!$B$12,"") | L38: =IF(G38<>"",G38*Assumptions!$B$13,"")
A39: Mainstream | B39: FRIGIDAIRE | C39: Gas Range (verify tag) | D39: 30" 5-Burner Gas Range SS | E39: 1 | G39: 2099 | H39: 929 | I39: Model tag verification required before advertising | J39: =IF(G39<>"",G39*Assumptions!$B$11,"") | K39: =IF(G39<>"",G39*Assumptions!$B$12,"") | L39: =IF(G39<>"",G39*Assumptions!$B$13,"")
A40: Mainstream | B40: ELECTROLUX | C40: ELTG7300AW | D40: Laundry Tower 4.4 washer + 8.0 gas dryer | E40: 1 | G40: 2199 | H40: 1699 | I40: Suggested ask 1399 / wholesale 1175 / floor 1099 | J40: =IF(G40<>"",G40*Assumptions!$B$11,"") | K40: =IF(G40<>"",G40*Assumptions!$B$12,"") | L40: =IF(G40<>"",G40*Assumptions!$B$13,"")
A41: HVAC | B41: GREENHECK | C41: SYNC-180SCEA-S1 | D41: SYNC180 Residential ERV 75-200 CFM | E41: 1 | F41: 1657 | G41: 1690 | H41: 1690 | I41: Suggested ask 1395 / volume 1095-1195 | J41: =IF(G41<>"",G41*Assumptions!$B$11,"") | K41: =IF(G41<>"",G41*Assumptions!$B$12,"") | L41: =IF(G41<>"",G41*Assumptions!$B$13,"")
...

Sheet Furniture
A1: FURNITURE / MATTRESSES / DISPLAYS (Moda Mobilya + Iskeceli + display units) - QUANTITIES NEED PHYSICAL COUNT
A3: Group | B3: Item | C3: SKU | D3: Vendor | E3: UnitCost | F3: RetailRate | G3: Qty | H3: Notes
A4: TV Console | B4: 70in TV Console w/o Doors (Silver/Black/White) | C4: E0000-70 | D4: MODA MOBILYA | E4: 120 | F4: 140-160 | G4: TBD | H4: Physical count needed - Zoho stock shows 0
A5: TV Console | B5: 78in TV Console w/o Doors (all colors) | C5: E0000-78 | D5: MODA MOBILYA | E5: 130 | F5: 175 | G5: TBD | H5: Physical count needed
A6: TV Console | B6: 95in TV Console w/o Doors (all colors) | C6: E0000-95 | D6: MODA MOBILYA | E6: 138 | F6: 186 | G6: TBD | H6: Physical count needed
A7: TV Console | B7: Haley 76in TV Console - White | C7: E1671-76-lacq | D7: MODA MOBILYA | E7: 151 | F7: 210 | G7: TBD
A8: TV Console | B8: Haley TV Console w/ Dual LED - Treviso | C8: E1671-76-a574 | D8: MODA MOBILYA | E8: 138 | F8: 186 | G8: TBD
A9: TV Console | B9: Lilianna TV Console (Black/Silver) | C9: E4399-76 | D9: MODA MOBILYA | E9: 212 | F9: 275 | G9: TBD
A10: TV Console | B10: Console w/ Dual LED (Black/Silver/White) | C10: E1847-66 | D10: MODA MOBILYA | E10: 172 | F10: 230 | G10: TBD
A11: Buffet | B11: 44in Buffet w/o Doors (all colors) | C11: D0000-44 | D11: MODA MOBILYA | E11: 90 | F11: 120-125 | G11: TBD
A12: Buffet | B12: 70in Buffet w/o Doors (all colors) | C12: D0000-70 | D12: MODA MOBILYA | E12: 100 | F12: 141 | G12: TBD
A13: Buffet | B13: 88in Buffet w/o Doors (Black/Silver) | C13: D0000-88 | D13: MODA MOBILYA | E13: 110 | F13: 165 | G13: TBD
A14: Door Sets | B14: Set of 2 Doors (Adrianna/Ianna/Myra/Sherry/Giovanna variants) | C14: various | D14: MODA MOBILYA | E14: 80-90 | F14: 108-120 | G14: TBD
A15: Door Sets | B15: Set of 3 Doors - Stream (White w/ Gold or Silver) | C15: Stream-3dr | D15: MODA MOBILYA | E15: 120 | F15: 177 | G15: TBD
A16: Mattress | B16: Bodrum Queen - Mattress Tailor Cotton 2000 | C16: MT-QN-COTTON 2000 | D16: ISKECELI | E16: 400 | F16: 1350 | G16: TBD
A17: Mattress | B17: Bodrum King - Mattress Tailor Cotton 2000 | C17: MT-KN-COTTON 2000 | D17: ISKECELI | E17: 450 | F17: 1650 | G17: TBD
A18: Mattress | B18: Ibiza Queen - Mattress Tailor Linen 2000 WP | C18: MT-QN-LINEN 2000 WP | D18: ISKECELI | E18: 570 | F18: 1650 | G18: TBD
... A21: Mattress | B21: Aruba King - Mattress Tailor Wool 3500 | C21: MT-KN-WOOL 3500 | D21: ISKECELI | E21: 665 | F21: 2150 | G21: TBD
A22: Mattress | B22: Santorini Queen - Mattress Tailor Linen 4500 | C22: MT-QN-LINEN 4500 | D22: ISKECELI | G22: TBD
A23: Display | B23: Display PAC | D23: XIAMEN BOYA | E23: 100 | G23: 19 | H23: Stock per 2024 Zoho export
A24: Display | B24: Metal Display Tower | D24: FOSHAN SHUNGZUN | E24: 112.23 | G24: 75 | H24: Stock per 2024 Zoho export
A25: Display | B25: Display Stand with LED Light | D25: FOSHAN SHUNGZUN | E25: 87.75 | G25: 75 | H25: Stock per 2024 Zoho export

Sheet Mining
A1: ULTIMA MINING - 13 EXPLORATION LICENSES, TURKIYE (Phase-1 complete: Matrix Geotechnologies 2024, 777 samples)
A2: Owner: Ultima Uluslararasi Tasimacilik Lojistik ve Dis Ticaret Ltd. Sti. | RISK: 2026 license & rehabilitation fees were unpaid as of June 2026 - VERIFY LICENSES ARE ALIVE BEFORE ANY MARKETING.
A4: Rank | B4: Site | C4: DepositType | D4: KeyResults | E4: LicenseNo | F4: PriorityRating | G4: Notes
A5: 1 | B5: Erzurum / Ispir | C5: Cu Sulfide / Porphyry Cu | D5: 5.08% Cu rock sample + Cu anomaly in 77% of stream samples; 2690 ppm As; 188 ppm Sb | E5: 202300537 | F5: 5/5
A6: 2 | B6: Balikesir / Kayaeli | C6: Epithermal Ag-Pb-Zn + Ni-Co Sulfide | D6: 110 ppm Ag stream (exceptional); 1936 ppm Zn + 500 ppm Pb; 89% Ni anomaly consistency | E6: 202300781 | F6: 5/5
A7: 3 | B7: Kastamonu / Taskopru | C7: Cu-Zn Massive Sulfide | D7: Cu anomaly in 100% of stream samples (29/29); 215.6 ppm Pb + 283.3 ppm Zn max | E7: 202300794 | F7: 5/5
A8: 4 | B8: Tokat / Turhal | C8: Epithermal Au-Cu | D8: 1.75 ppm Au rock + 0.64 ppm Au stream; 69.4 ppm Mo; malachite-bearing quartzite | F8: 4/5
A9: 5 | B9: Kirsehir / Cicekdagi | C9: Porphyry / Epithermal | D9: 4265 ppm Bi + 1277 ppm Mo rock | F9: 4/5
A10: 6 | B10: Adiyaman / Kocali | C10: Ni-Cu-Co Mafic | D10: 88% Cu+Ni+Co triple anomaly | F10: 4/5
A11: 7 | B11: Mersin / Toros | C11: Zn-Pb MVT Carbonate | D11: 93% Ni + 71% Zn stream anomaly | F11: 3/5
A12: 8 | B12: Ordu / Mesudiye | C12: VMS Fe-Cu-Zn | D12: 93% Fe + 67% Cu stream anomaly | F12: 3/5
A13: 9 | B13: Amasya / Hamamozu | C13: Epithermal Hg-Au | D13: 32% Hg anomaly + 0.7 ppm Ag | F13: 3/5
A14: 10 | B14: Malatya / Puturge | C14: IOCG / Skarn Fe-Zn | D14: 48% Fe rock + 56% Zn stream | F14: 3/5
A15: 11 | B15: TBD (see full ULTIMA report) | G15: Sites 11-13 in full report PDF - extract Sunday
A16: 12 | B16: TBD (see full ULTIMA report)
A17: 13 | B17: TBD (see full ULTIMA report)

Sheet Assumptions
A1: PRICING TIER ASSUMPTIONS (edit the blue cells; every tier column recalculates)
A3: SLABS
A4: Quick-sale multiplier vs List A (bulk/one-lot exit, 7-21 days) | B4: 0.7
A5: Mid = List A (Jan-2025 offer sheet). Slow = List B (Jun-2025 list).
A6: EQUIPMENT
A7: Quick-sale multiplier vs unit cost (dealer/wholesale exit) | B7: 0.55
A8: Mid multiplier vs unit cost (direct end-user sale) | B8: 0.75
A9: APPLIANCES
A10: Quick multiplier vs MSRP (bulk to reseller/liquidator) | B10: 0.45
A11: Mid multiplier vs MSRP (contractor packages) | B11: 0.55
A12: Slow multiplier vs MSRP (retail one-by-one) | B12: 0.7
A15: SOURCES:
A16: Slabs: 'Inventory of Slabs and Tiles.xlsx' (List A, Jan-2025, incl. 25% bulk-discount footer) + 'Inventory of Slabs Northvale June 2025.xlsx' (List B). Google Drive.
A17: Vietnam quartz actual purchase cost $481.28/slab from BZ Zoho item export ('Item (1).xlsx').
A18: Equipment: 'Forklift and Warehouse Equipment Inventory (1).xlsx' (2024 stock summary w/ costs); on-hand flags from 'Forklift and Warehouse Equipment Inventory May 2026.xls'.
A19: Appliances: 'APPLIANCES (1) (1).xlsx' (cost+MSRP) + 'APPLIANCES_updated_retail_prices.xlsx' (verified retail) + Milhurst pricing pack (2026-06-13).
A20: Mining: 'ULTIMA_Arama_Projeleri_Sunum.pdf' (13-site Phase-1 report).
A21: ALL quantities are per the source files - physical verification required before binding offers.
A22: LEGAL: Seller of record = Milhurst Mills (agency structure). No offer without signed agency agreement + counsel clearance (Zazella & Singer) - see SALES_PLAN_30_DAYS.md.
